[1m============================= test session starts ==============================[0m
platform linux -- Python 3.11.10, pytest-7.4.4, pluggy-1.0.0 -- /opt/conda/envs/sage/bin/python
cachedir: .pytest_cache
rootdir: /home/tjy/SAGE
plugins: typeguard-4.3.0, mock-3.14.1, anyio-4.6.0
[1mcollecting ... [0mcollected 8 items

sage/service/tests/test_integrated_service_call.py::test_integrated_service_call [32mPASSED[0m[33m [ 12%][0m
sage/service/tests/test_service_syntax.py::TestServiceSyntax::test_async_service_call_syntax [31mFAILED[0m[31m [ 25%][0m
sage/service/tests/test_service_syntax.py::TestServiceSyntax::test_call_service_async_property_access [32mPASSED[0m[31m [ 37%][0m
sage/service/tests/test_service_syntax.py::TestServiceSyntax::test_call_service_property_access [32mPASSED[0m[31m [ 50%][0m
sage/service/tests/test_service_syntax.py::TestServiceSyntax::test_multiple_service_access [31mFAILED[0m[31m [ 62%][0m
sage/service/tests/test_service_syntax.py::TestServiceSyntax::test_service_access_without_context [32mPASSED[0m[31m [ 75%][0m
sage/service/tests/test_service_syntax.py::TestServiceSyntax::test_sync_service_call_syntax [31mFAILED[0m[31m [ 87%][0m
sage/service/tests/test_service_syntax.py::TestIntegratedServiceCall::test_real_service_manager_integration [32mPASSED[0m[31m [100%][0m

=================================== FAILURES ===================================
[31m[1m_______________ TestServiceSyntax.test_async_service_call_syntax _______________[0m
[1m[31m/opt/conda/envs/sage/lib/python3.11/unittest/mock.py[0m:1375: in patched
    [94mwith[39;49;00m [96mself[39;49;00m.decoration_helper(patched,[90m[39;49;00m
[1m[31m/opt/conda/envs/sage/lib/python3.11/contextlib.py[0m:137: in __enter__
    [94mreturn[39;49;00m [96mnext[39;49;00m([96mself[39;49;00m.gen)[90m[39;49;00m
[1m[31m/opt/conda/envs/sage/lib/python3.11/unittest/mock.py[0m:1357: in decoration_helper
    arg = exit_stack.enter_context(patching)[90m[39;49;00m
[1m[31m/opt/conda/envs/sage/lib/python3.11/contextlib.py[0m:517: in enter_context
    result = _enter(cm)[90m[39;49;00m
[1m[31m/opt/conda/envs/sage/lib/python3.11/unittest/mock.py[0m:1430: in __enter__
    [96mself[39;49;00m.target = [96mself[39;49;00m.getter()[90m[39;49;00m
[1m[31m/opt/conda/envs/sage/lib/python3.11/pkgutil.py[0m:715: in resolve_name
    result = [96mgetattr[39;49;00m(result, p)[90m[39;49;00m
[1m[31mE   AttributeError: module 'sage_core' has no attribute 'service'[0m
[31m[1m________________ TestServiceSyntax.test_multiple_service_access ________________[0m
[1m[31msage/service/tests/test_service_syntax.py[0m:136: in test_multiple_service_access
    [94mwith[39;49;00m patch([33m'[39;49;00m[33msage_core.service.service_caller.ServiceManager[39;49;00m[33m'[39;49;00m) [94mas[39;49;00m mock_sm_class:[90m[39;49;00m
[1m[31m/opt/conda/envs/sage/lib/python3.11/unittest/mock.py[0m:1430: in __enter__
    [96mself[39;49;00m.target = [96mself[39;49;00m.getter()[90m[39;49;00m
[1m[31m/opt/conda/envs/sage/lib/python3.11/pkgutil.py[0m:715: in resolve_name
    result = [96mgetattr[39;49;00m(result, p)[90m[39;49;00m
[1m[31mE   AttributeError: module 'sage_core' has no attribute 'service'[0m
[31m[1m_______________ TestServiceSyntax.test_sync_service_call_syntax ________________[0m
[1m[31m/opt/conda/envs/sage/lib/python3.11/unittest/mock.py[0m:1375: in patched
    [94mwith[39;49;00m [96mself[39;49;00m.decoration_helper(patched,[90m[39;49;00m
[1m[31m/opt/conda/envs/sage/lib/python3.11/contextlib.py[0m:137: in __enter__
    [94mreturn[39;49;00m [96mnext[39;49;00m([96mself[39;49;00m.gen)[90m[39;49;00m
[1m[31m/opt/conda/envs/sage/lib/python3.11/unittest/mock.py[0m:1357: in decoration_helper
    arg = exit_stack.enter_context(patching)[90m[39;49;00m
[1m[31m/opt/conda/envs/sage/lib/python3.11/contextlib.py[0m:517: in enter_context
    result = _enter(cm)[90m[39;49;00m
[1m[31m/opt/conda/envs/sage/lib/python3.11/unittest/mock.py[0m:1430: in __enter__
    [96mself[39;49;00m.target = [96mself[39;49;00m.getter()[90m[39;49;00m
[1m[31m/opt/conda/envs/sage/lib/python3.11/pkgutil.py[0m:715: in resolve_name
    result = [96mgetattr[39;49;00m(result, p)[90m[39;49;00m
[1m[31mE   AttributeError: module 'sage_core' has no attribute 'service'[0m
[33m=============================== warnings summary ===============================[0m
sage/service/tests/test_integrated_service_call.py:40
  /home/tjy/SAGE/sage/service/tests/test_integrated_service_call.py:40: PytestCollectionWarning: cannot collect test class 'TestCacheService' because it has a __init__ constructor (from: sage/service/tests/test_integrated_service_call.py)
    class TestCacheService:

sage/service/tests/test_integrated_service_call.py:58
  /home/tjy/SAGE/sage/service/tests/test_integrated_service_call.py:58: PytestCollectionWarning: cannot collect test class 'TestDatabaseService' because it has a __init__ constructor (from: sage/service/tests/test_integrated_service_call.py)
    class TestDatabaseService:

sage/service/tests/test_integrated_service_call.py:80
  /home/tjy/SAGE/sage/service/tests/test_integrated_service_call.py:80: PytestCollectionWarning: cannot collect test class 'TestFunction' because it has a __init__ constructor (from: sage/service/tests/test_integrated_service_call.py)
    class TestFunction(BaseFunction):

sage/service/tests/test_service_syntax.py:34
  /home/tjy/SAGE/sage/service/tests/test_service_syntax.py:34: PytestCollectionWarning: cannot collect test class 'TestFunction' because it has a __init__ constructor (from: sage/service/tests/test_service_syntax.py)
    class TestFunction(BaseFunction):

sage/service/tests/test_integrated_service_call.py::test_integrated_service_call
  /opt/conda/envs/sage/lib/python3.11/site-packages/_pytest/python.py:198: PytestReturnNotNoneWarning: Expected None, but sage/service/tests/test_integrated_service_call.py::test_integrated_service_call returned False, which will be an error in a future version of pytest.  Did you mean to use `assert` instead of `return`?
    warnings.warn(

-- Docs: https://docs.pytest.org/en/stable/how-to/capture-warnings.html
[36m[1m=========================== short test summary info ============================[0m
[31mFAILED[0m sage/service/tests/test_service_syntax.py::[1mTestServiceSyntax::test_async_service_call_syntax[0m - AttributeError: module 'sage_core' has no attribute 'service'
[31mFAILED[0m sage/service/tests/test_service_syntax.py::[1mTestServiceSyntax::test_multiple_service_access[0m - AttributeError: module 'sage_core' has no attribute 'service'
[31mFAILED[0m sage/service/tests/test_service_syntax.py::[1mTestServiceSyntax::test_sync_service_call_syntax[0m - AttributeError: module 'sage_core' has no attribute 'service'
[31m============== [31m[1m3 failed[0m, [32m5 passed[0m, [33m5 warnings[0m[31m in 63.97s (0:01:03)[0m[31m ==============[0m
